<?xml version="1.0" ?>
<!-- =================================================================================== -->
<!-- |    This document was autogenerated by xacro from arm.urdf.xacro                 | -->
<!-- |    EDITING THIS FILE BY HAND IS NOT RECOMMENDED                                 | -->
<!-- =================================================================================== -->
<robot name="SEED-Arm-Mover-typeC" xmlns:xacro="http://ros.org/wiki/xacro">
  <!-- ============================   typeF_upper   ============================ -->
  <link name="waist_link">
    <visual>
      <origin rpy="0 0 0" xyz="0 0 0"/>
      <geometry>
        <mesh filename="package://seed_r7_description/meshes/typeC_arm/shoulder_y.dae" scale="1 1 1"/>
      </geometry>
    </visual>
    <collision>
      <origin rpy="0 0 0" xyz="0 0 0.045"/>
      <geometry>
        <cylinder length="0.07" radius="0.04"/>
        <!--<mesh filename="package://seed_r7_description/meshes/typeC_arm/shoulder_y.dae" scale="1 1 1" />-->
      </geometry>
    </collision>
    <inertial>
      <mass value="1.257"/>
      <origin rpy="0 -0 0" xyz="0 0 0.0"/>
      <inertia ixx="0.034" ixy="0" ixz="0" iyy="0.034" iyz="0" izz="0.018"/>
    </inertial>
  </link>
  <gazebo reference="waist_link">
    <mu1>0.9</mu1>
    <mu2>0.9</mu2>
  </gazebo>
  <link name="shoulder_link">
    <visual>
      <origin rpy="0 0 0" xyz="0 0 0"/>
      <geometry>
        <mesh filename="package://seed_r7_description/meshes/typeC_arm/shoulder_p.dae" scale="1 1 1"/>
      </geometry>
    </visual>
    <collision>
      <origin rpy="0 0 0" xyz="-0.01 0 0.025"/>
      <geometry>
        <box size="0.07 0.05 0.05"/>
        <!--<cylinder length="0.03" radius="0.04"/>-->
        <!--<mesh filename="package://seed_r7_description/meshes/typeC_arm/shoulder_p.dae" scale="1 1 1" />-->
      </geometry>
    </collision>
    <inertial>
      <mass value="0.242"/>
      <origin rpy="0 -0 0" xyz="0 -0.02 0.015"/>
      <inertia ixx="0.00133" ixy="0" ixz="0" iyy="0.001" iyz="0" izz="0.00133"/>
    </inertial>
  </link>
  <gazebo reference="shoulder_link">
    <mu1>0.9</mu1>
    <mu2>0.9</mu2>
  </gazebo>
  <link name="upperarm_link">
    <visual>
      <origin rpy="0 -0 0" xyz="0 0 0"/>
      <geometry>
        <mesh filename="package://seed_r7_description/meshes/typeC_arm/upperarm.dae" scale="1 1 1"/>
      </geometry>
    </visual>
    <collision>
      <origin rpy="0 0 0" xyz="-0.02 0 0.16"/>
      <geometry>
        <box size="0.1 0.08 0.3"/>
        <!--<cylinder length="0.3" radius="0.04"/>-->
        <!--<mesh filename="package://seed_r7_description/meshes/typeC_arm/upperarm.dae" scale="1 1 1" />-->
      </geometry>
    </collision>
    <inertial>
      <mass value="0.574"/>
      <origin rpy="0 -0 0" xyz="0.005 0 -0.0654"/>
      <inertia ixx="0.00214" ixy="0" ixz="0" iyy="0.00217" iyz="0" izz="0.003"/>
    </inertial>
  </link>
  <gazebo reference="upperarm_link">
    <mu1>0.9</mu1>
    <mu2>0.9</mu2>
  </gazebo>
  <link name="elbow_link">
    <visual>
      <origin rpy="0 0 0" xyz="-0.022 0 0.02"/>
      <geometry>
        <mesh filename="package://seed_r7_description/meshes/typeC_arm/elbow.dae" scale="1 1 1"/>
      </geometry>
    </visual>
    <collision>
      <origin rpy="0 0 0" xyz="-0.03 0 0.06"/>
      <geometry>
        <cylinder length="0.15" radius="0.035"/>
        <!--<mesh filename="package://seed_r7_description/meshes/typeC_arm/elbow.dae" scale="1 1 1" />-->
      </geometry>
    </collision>
    <inertial>
      <mass value="0.711"/>
      <origin rpy="0 -0 0" xyz="-0.03 0 -0.0546"/>
      <inertia ixx="0.00178" ixy="0" ixz="0" iyy="0.00179" iyz="0" izz="0.0035"/>
    </inertial>
  </link>
  <gazebo reference="elbow_link">
    <mu1>0.9</mu1>
    <mu2>0.9</mu2>
  </gazebo>
  <link name="forearm_link">
    <visual>
      <origin rpy="0 0 0" xyz="0 0 0"/>
      <geometry>
        <mesh filename="package://seed_r7_description/meshes/typeC_arm/forearm.dae" scale="1 1 1"/>
      </geometry>
    </visual>
    <collision>
      <origin rpy="0 0 0" xyz="0 0 0.06"/>
      <geometry>
        <box size="0.05 0.08 0.12"/>
        <!--<cylinder length="0.12" radius="0.04"/>-->
        <!--<mesh filename="package://seed_r7_description/meshes/typeC_arm/forearm.dae" scale="1 1 1" />-->
      </geometry>
    </collision>
    <inertial>
      <mass value="0.132"/>
      <origin rpy="0 -0 0" xyz="0.006 0 -0.0738"/>
      <inertia ixx="0.0007" ixy="0" ixz="0" iyy="0.0007" iyz="0" izz="0.0004"/>
    </inertial>
  </link>
  <gazebo reference="forearm_link">
    <mu1>0.9</mu1>
    <mu2>0.9</mu2>
  </gazebo>
  <link name="wrist_r_link">
    <visual>
      <origin rpy="0 0 0" xyz="0 0 0"/>
      <geometry>
        <mesh filename="package://seed_r7_description/meshes/typeC_arm/wrist_r.dae" scale="1 1 1"/>
      </geometry>
    </visual>
    <collision>
      <origin rpy="1.57 1.57 0" xyz="0 0 0"/>
      <geometry>
        <cylinder length="0.03" radius="0.005"/>
        <!--<mesh filename="package://seed_r7_description/meshes/typeC_arm/wrist_r.dae" scale="1 1 1" />-->
      </geometry>
    </collision>
    <inertial>
      <mass value="0.05"/>
      <origin rpy="0 -0 0" xyz="0 0 0"/>
      <inertia ixx="0.0001" ixy="0" ixz="0" iyy="0.0001" iyz="0" izz="0.0001"/>
    </inertial>
  </link>
  <gazebo reference="wrist_roll">
    <mu1>0.9</mu1>
    <mu2>0.9</mu2>
  </gazebo>
  <link name="wrist_p_link">
    <visual>
      <origin rpy="0 0 0" xyz="0 0 0"/>
      <geometry>
        <mesh filename="package://seed_r7_description/meshes/typeC_arm/wrist_p.dae" scale="1 1 1"/>
      </geometry>
    </visual>
    <collision>
      <origin rpy="1.570 0 0" xyz="0 0 0"/>
      <geometry>
        <cylinder length="0.03" radius="0.005"/>
        <!--<mesh filename="package://seed_r7_description/meshes/typeC_arm/wrist_p.dae" scale="1 1 1" />-->
      </geometry>
    </collision>
    <inertial>
      <mass value="0.05"/>
      <origin rpy="0 -0 0" xyz="0 0 0"/>
      <inertia ixx="0.0001" ixy="0" ixz="0" iyy="0.0001" iyz="0" izz="0.0001"/>
    </inertial>
  </link>
  <gazebo reference="wrist_pitch">
    <mu1>0.9</mu1>
    <mu2>0.9</mu2>
  </gazebo>
  <joint name="shoulder_y_joint" type="revolute">
    <parent link="waist_link"/>
    <child link="shoulder_link"/>
    <origin rpy="0 0 0 " xyz="0 0 0.083"/>
    <axis xyz="0 0 1"/>
    <limit effort="100" lower="-2.09" upper="2.09" velocity="1.2"/>
    <dynamics damping="0.2" friction="0"/>
  </joint>
  <transmission name="shoulder_y_joint_trans">
    <type>transmission_interface/SimpleTransmission</type>
    <joint name="shoulder_y_joint">
      <!-- dupricated in kinetic -->
      <!--hardwareInterface>hardware_interface/EffortJointInterface</hardwareInterface-->
      <!--hardwareInterface>EffortJointInterface</hardwareInterface-->
      <hardwareInterface>VelocityJointInterface</hardwareInterface>
    </joint>
    <actuator name="shoulder_y_joint_motor">
      <!-- dupricated in kinetic -->
      <!--hardwareInterface>hardware_interface/EffortJointInterface</hardwareInterface-->
      <!--hardwareInterface>EffortJointInterface</hardwareInterface-->
      <hardwareInterface>VelocityJointInterface</hardwareInterface>
      <mechanicalReduction>1</mechanicalReduction>
    </actuator>
  </transmission>
  <gazebo reference="shoulder_y_joint">
    <implicitSpringDamper>0</implicitSpringDamper>
  </gazebo>
  <joint name="shoulder_p_joint" type="revolute">
    <parent link="shoulder_link"/>
    <child link="upperarm_link"/>
    <origin rpy="0 0 0 " xyz="0.0055 0 0.028"/>
    <axis xyz="0 1 0"/>
    <!-- from -88 to 15 degrees-->
    <limit effort="200" lower="0" upper="1.57" velocity="0.6"/>
    <dynamics damping="0.2" friction="0"/>
  </joint>
  <transmission name="shoulder_p_joint_trans">
    <type>transmission_interface/SimpleTransmission</type>
    <joint name="shoulder_p_joint">
      <!-- dupricated in kinetic -->
      <!--hardwareInterface>hardware_interface/EffortJointInterface</hardwareInterface-->
      <!--hardwareInterface>EffortJointInterface</hardwareInterface-->
      <hardwareInterface>VelocityJointInterface</hardwareInterface>
    </joint>
    <actuator name="shoulder_p_joint_motor">
      <!-- dupricated in kinetic -->
      <!--hardwareInterface>hardware_interface/EffortJointInterface</hardwareInterface-->
      <!--hardwareInterface>EffortJointInterface</hardwareInterface-->
      <hardwareInterface>VelocityJointInterface</hardwareInterface>
      <mechanicalReduction>1</mechanicalReduction>
    </actuator>
  </transmission>
  <gazebo reference="shoulder_p_joint">
    <implicitSpringDamper>0</implicitSpringDamper>
  </gazebo>
  <joint name="elbow_joint" type="revolute">
    
   u 
    <parent link="upperarm_link"/>
    <child link="elbow_link"/>
    <origin rpy="0 -0 0 " xyz="0.02 0 0.322"/>
    <axis xyz="0 1 0"/>
    <!-- from -171 to 0 degrees-->
    <limit effort="100" lower="0" upper="3.14" velocity="1.2"/>
    <dynamics damping="0.2" friction="0"/>
  </joint>
  <transmission name="elbow_joint_trans">
    <type>transmission_interface/SimpleTransmission</type>
    <joint name="elbow_joint">
      <!-- dupricated in kinetic -->
      <!--hardwareInterface>hardware_interface/EffortJointInterface</hardwareInterface-->
      <!--hardwareInterface>EffortJointInterface</hardwareInterface-->
      <hardwareInterface>VelocityJointInterface</hardwareInterface>
    </joint>
    <actuator name="elbow_joint_motor">
      <!-- dupricated in kinetic -->
      <!--hardwareInterface>hardware_interface/EffortJointInterface</hardwareInterface-->
      <!--hardwareInterface>EffortJointInterface</hardwareInterface-->
      <hardwareInterface>VelocityJointInterface</hardwareInterface>
      <mechanicalReduction>1</mechanicalReduction>
    </actuator>
  </transmission>
  <gazebo reference="elbow_joint">
    <implicitSpringDamper>0</implicitSpringDamper>
  </gazebo>
  <joint name="wrist_y_joint" type="revolute">
    <parent link="elbow_link"/>
    <child link="forearm_link"/>
    <origin rpy="0 -0 0 " xyz="-0.022 0 0.138"/>
    <axis xyz="0 0 1"/>
    <!-- from -180 to 180 degrees-->
    <limit effort="100" lower="-2.09" upper="2.09" velocity="1.3"/>
    <dynamics damping="0.2" friction="0"/>
  </joint>
  <transmission name="wrist_y_joint_trans">
    <type>transmission_interface/SimpleTransmission</type>
    <joint name="wrist_y_joint">
      <!-- dupricated in kinetic -->
      <!--hardwareInterface>hardware_interface/EffortJointInterface</hardwareInterface-->
      <!--hardwareInterface>EffortJointInterface</hardwareInterface-->
      <hardwareInterface>VelocityJointInterface</hardwareInterface>
    </joint>
    <actuator name="wrist_y_joint_motor">
      <!-- dupricated in kinetic -->
      <!--hardwareInterface>hardware_interface/EffortJointInterface</hardwareInterface-->
      <!--hardwareInterface>EffortJointInterface</hardwareInterface-->
      <hardwareInterface>VelocityJointInterface</hardwareInterface>
      <mechanicalReduction>1</mechanicalReduction>
    </actuator>
  </transmission>
  <gazebo reference="wrist_y_joint">
    <implicitSpringDamper>0</implicitSpringDamper>
  </gazebo>
  <joint name="wrist_r_joint" type="revolute">
    <parent link="forearm_link"/>
    <child link="wrist_r_link"/>
    <origin rpy="0 -0 1.570 " xyz="0 0 0.132"/>
    <axis xyz="0 1 0"/>
    <!-- from -25 to 85 degrees-->
    <limit effort="100" lower="-0.35" upper="0.35" velocity="1.05"/>
    <dynamics damping="0.2" friction="0"/>
  </joint>
  <transmission name="wrist_r_joint_trans">
    <type>transmission_interface/SimpleTransmission</type>
    <joint name="wrist_r_joint">
      <!-- dupricated in kinetic -->
      <!--hardwareInterface>hardware_interface/EffortJointInterface</hardwareInterface-->
      <!--hardwareInterface>EffortJointInterface</hardwareInterface-->
      <hardwareInterface>VelocityJointInterface</hardwareInterface>
    </joint>
    <actuator name="wrist_r_joint_motor">
      <!-- dupricated in kinetic -->
      <!--hardwareInterface>hardware_interface/EffortJointInterface</hardwareInterface-->
      <!--hardwareInterface>EffortJointInterface</hardwareInterface-->
      <hardwareInterface>VelocityJointInterface</hardwareInterface>
      <mechanicalReduction>1</mechanicalReduction>
    </actuator>
  </transmission>
  <gazebo reference="wrist_r_joint">
    <implicitSpringDamper>0</implicitSpringDamper>
  </gazebo>
  <joint name="wrist_p_joint" type="revolute">
    <parent link="wrist_r_link"/>
    <child link="wrist_p_link"/>
    <origin rpy="0 0 -1.570 " xyz="0 -0.005 0"/>
    <axis xyz="0 1 0"/>
    <!-- from -5 to 5 degrees-->
    <limit effort="100" lower="-0.7" upper="0.87" velocity="1.4"/>
    <dynamics damping="0.2" friction="0"/>
  </joint>
  <transmission name="wrist_p_joint_trans">
    <type>transmission_interface/SimpleTransmission</type>
    <joint name="wrist_p_joint">
      <!-- dupricated in kinetic -->
      <!--hardwareInterface>hardware_interface/EffortJointInterface</hardwareInterface-->
      <!--hardwareInterface>EffortJointInterface</hardwareInterface-->
      <hardwareInterface>VelocityJointInterface</hardwareInterface>
    </joint>
    <actuator name="wrist_p_joint_motor">
      <!-- dupricated in kinetic -->
      <!--hardwareInterface>hardware_interface/EffortJointInterface</hardwareInterface-->
      <!--hardwareInterface>EffortJointInterface</hardwareInterface-->
      <hardwareInterface>VelocityJointInterface</hardwareInterface>
      <mechanicalReduction>1</mechanicalReduction>
    </actuator>
  </transmission>
  <gazebo reference="wrist_p_joint">
    <implicitSpringDamper>0</implicitSpringDamper>
  </gazebo>
  <joint name="wrist_connector" type="fixed">
    <parent link="wrist_p_link"/>
    <child link="r_hand_link"/>
    <origin rpy="0 3.14 -1.570 " xyz="0 0 -0.003"/>
    <!-- from -25 to 85 degrees-->
  </joint>
  <transmission name="wrist_connector_trans">
    <type>transmission_interface/SimpleTransmission</type>
    <joint name="wrist_connector">
      <!-- dupricated in kinetic -->
      <!--hardwareInterface>hardware_interface/EffortJointInterface</hardwareInterface-->
      <!--hardwareInterface>EffortJointInterface</hardwareInterface-->
      <hardwareInterface>VelocityJointInterface</hardwareInterface>
    </joint>
    <actuator name="wrist_connector_motor">
      <!-- dupricated in kinetic -->
      <!--hardwareInterface>hardware_interface/EffortJointInterface</hardwareInterface-->
      <!--hardwareInterface>EffortJointInterface</hardwareInterface-->
      <hardwareInterface>VelocityJointInterface</hardwareInterface>
      <mechanicalReduction>1</mechanicalReduction>
    </actuator>
  </transmission>
  <gazebo reference="wrist_connector">
    <implicitSpringDamper>0</implicitSpringDamper>
  </gazebo>
  <!-- ============================   Hand(trx_s)   ============================ -->
  <!-- prefix is "r" or "l" -->
  <!-- reflect=1 is rightside, reflect=-1 is leftside -->
  <link name="r_hand_link">
    <visual>
      <origin rpy="0 -0 0.0" xyz="0 0 0"/>
      <geometry>
        <mesh filename="package://seed_r7_description/meshes/trx_s/RARM_LINK7_mesh.dae" scale="1 1 1"/>
      </geometry>
    </visual>
    <collision>
      <origin rpy="0.7 0 0" xyz="0 0 -0.093"/>
      <geometry>
        <box size="0.036 0.070 0.030"/>
      </geometry>
    </collision>
    <collision>
      <origin rpy="-0.1 0 0" xyz="0 -0.007 -0.055"/>
      <geometry>
        <box size="0.036 0.050 0.070"/>
      </geometry>
    </collision>
    <inertial>
      <mass value="0.183"/>
      <origin rpy="0 -0 0" xyz="0 0 -0.0875"/>
      <inertia ixx="0.000601" ixy="0" ixz="0" iyy="0.00055" iyz="0" izz="0.000102"/>
    </inertial>
  </link>
  <gazebo reference="r_hand_link">
    <mu1>0.9</mu1>
    <mu2>0.9</mu2>
  </gazebo>
  <link name="r_indexbase_link">
    <visual>
      <origin rpy="0 -0 0.0" xyz="0 0.013 0.115"/>
      <geometry>
        <mesh filename="package://seed_r7_description/meshes/trx_s/RARM_INDEX_LINK1_mesh.dae" scale="1 1 1"/>
      </geometry>
    </visual>
    <collision>
      <origin rpy="-0.85 0 0" xyz="0 0.013494 -0.021422"/>
      <geometry>
        <box size="0.041 0.061 0.016"/>
        <!-- 0.85 -->
      </geometry>
    </collision>
    <inertial>
      <mass value="0.1"/>
      <origin rpy="0 0 0" xyz="0 0.014 -0.021"/>
      <inertia ixx="0.001" ixy="0" ixz="0" iyy="0.0001" iyz="0" izz="0.0001"/>
    </inertial>
  </link>
  <gazebo reference="r_indexbase_link">
    <mu1>0.9</mu1>
    <mu2>0.9</mu2>
  </gazebo>
  <link name="r_indexmid_link">
    <visual>
      <origin rpy="0 -0 0.0" xyz="0 -0.015754 0.149615"/>
      <geometry>
        <mesh filename="package://seed_r7_description/meshes/trx_s/RARM_INDEX_LINK2_mesh.dae" scale="1 1 1"/>
      </geometry>
    </visual>
    <collision>
      <origin rpy="-0.3 0 0" xyz="0 0.014 -0.008"/>
      <!-- 0.3 -->
      <geometry>
        <box size="0.034 0.030 0.016"/>
      </geometry>
    </collision>
    <inertial>
      <mass value="0.1"/>
      <origin rpy="0 0 0" xyz="0 0.014 -0.008"/>
      <inertia ixx="0.001" ixy="0" ixz="0" iyy="0.0001" iyz="0" izz="0.0001"/>
    </inertial>
  </link>
  <gazebo reference="r_indexmid_link">
    <mu1>0.9</mu1>
    <mu2>0.9</mu2>
  </gazebo>
  <link name="r_indexend_link">
    <visual>
      <origin rpy="0 -0 0.0" xyz="0 -0.03747 0.162972"/>
      <geometry>
        <mesh filename="package://seed_r7_description/meshes/trx_s/RARM_INDEX_LINK3_mesh.dae" scale="1 1 1"/>
      </geometry>
    </visual>
    <collision>
      <origin rpy="0 0 0" xyz="0 0.013 0.004"/>
      <!-- 0.0 -->
      <geometry>
        <box size="0.040 0.028 0.016"/>
      </geometry>
    </collision>
    <inertial>
      <mass value="0.1"/>
      <origin rpy="0 0 0" xyz="0 0.02 0"/>
      <inertia ixx="0.0001" ixy="0" ixz="0" iyy="0.0001" iyz="0" izz="0.0001"/>
    </inertial>
  </link>
  <gazebo reference="r_indexend_link">
    <mu1>0.9</mu1>
    <mu2>0.9</mu2>
  </gazebo>
  <link name="r_thumb_link">
    <visual>
      <origin rpy="0 -0 0.0" xyz="0 -0.022355 0.079645"/>
      <geometry>
        <mesh filename="package://seed_r7_description/meshes/trx_s/RARM_THUMB_LINK_mesh.dae" scale="1 1 1"/>
      </geometry>
    </visual>
    <collision>
      <origin rpy="0.63 0 0" xyz="0.0 0.019645 -0.010355"/>
      <geometry>
        <box size="0.012 0.008 0.050"/>
      </geometry>
    </collision>
    <collision>
      <origin rpy="0.1 0 0" xyz="0.0 0.035645 -0.050355"/>
      <geometry>
        <box size="0.012 0.008 0.050"/>
      </geometry>
    </collision>
    <inertial>
      <mass value="0.1"/>
      <origin rpy="0 0 0" xyz="0 0.05 -0.06"/>
      <inertia ixx="0.001" ixy="0" ixz="0" iyy="0.0001" iyz="0" izz="0.0001"/>
    </inertial>
  </link>
  <gazebo reference="r_thumb_link">
    <mu1>0.9</mu1>
    <mu2>0.9</mu2>
  </gazebo>
  <joint name="r_indexbase_joint" type="revolute">
    <parent link="r_hand_link"/>
    <child link="r_indexbase_link"/>
    <origin rpy="0 -0 0 " xyz="0 -0.013 -0.115"/>
    <axis xyz="1 0 0"/>
    <limit effort="100" lower="-3.14159" upper="3.14159" velocity="0.5"/>
    <dynamics damping="0.2" friction="0"/>
  </joint>
  <transmission name="r_indexbase_joint_trans">
    <type>transmission_interface/SimpleTransmission</type>
    <joint name="r_indexbase_joint">
      <!-- dupricated in kinetic -->
      <!--hardwareInterface>hardware_interface/EffortJointInterface</hardwareInterface-->
      <!--hardwareInterface>EffortJointInterface</hardwareInterface-->
      <hardwareInterface>VelocityJointInterface</hardwareInterface>
    </joint>
    <actuator name="r_indexbase_joint_motor">
      <!-- dupricated in kinetic -->
      <!--hardwareInterface>hardware_interface/EffortJointInterface</hardwareInterface-->
      <!--hardwareInterface>EffortJointInterface</hardwareInterface-->
      <hardwareInterface>VelocityJointInterface</hardwareInterface>
      <mechanicalReduction>1</mechanicalReduction>
    </actuator>
  </transmission>
  <gazebo reference="r_indexbase_joint">
    <implicitSpringDamper>0</implicitSpringDamper>
  </gazebo>
  <joint name="r_indexmid_joint" type="revolute">
    <parent link="r_indexbase_link"/>
    <child link="r_indexmid_link"/>
    <origin rpy="0 -0 0 " xyz="0 0.028754 -0.034615"/>
    <axis xyz="1 0 0"/>
    <limit effort="100" lower="-3.14159" upper="3.14159" velocity="0.5"/>
    <dynamics damping="0.2" friction="0"/>
  </joint>
  <transmission name="r_indexmid_joint_trans">
    <type>transmission_interface/SimpleTransmission</type>
    <joint name="r_indexmid_joint">
      <!-- dupricated in kinetic -->
      <!--hardwareInterface>hardware_interface/EffortJointInterface</hardwareInterface-->
      <!--hardwareInterface>EffortJointInterface</hardwareInterface-->
      <hardwareInterface>VelocityJointInterface</hardwareInterface>
    </joint>
    <actuator name="r_indexmid_joint_motor">
      <!-- dupricated in kinetic -->
      <!--hardwareInterface>hardware_interface/EffortJointInterface</hardwareInterface-->
      <!--hardwareInterface>EffortJointInterface</hardwareInterface-->
      <hardwareInterface>VelocityJointInterface</hardwareInterface>
      <mechanicalReduction>1</mechanicalReduction>
    </actuator>
  </transmission>
  <gazebo reference="r_indexmid_joint">
    <implicitSpringDamper>0</implicitSpringDamper>
  </gazebo>
  <joint name="r_indexend_joint" type="revolute">
    <parent link="r_indexmid_link"/>
    <child link="r_indexend_link"/>
    <origin rpy="0 -0 0 " xyz="0 0.021716 -0.013357"/>
    <axis xyz="1 0 0"/>
    <limit effort="100" lower="-3.14159" upper="3.14159" velocity="0.5"/>
    <dynamics damping="0.2" friction="0"/>
  </joint>
  <transmission name="r_indexend_joint_trans">
    <type>transmission_interface/SimpleTransmission</type>
    <joint name="r_indexend_joint">
      <!-- dupricated in kinetic -->
      <!--hardwareInterface>hardware_interface/EffortJointInterface</hardwareInterface-->
      <!--hardwareInterface>EffortJointInterface</hardwareInterface-->
      <hardwareInterface>VelocityJointInterface</hardwareInterface>
    </joint>
    <actuator name="r_indexend_joint_motor">
      <!-- dupricated in kinetic -->
      <!--hardwareInterface>hardware_interface/EffortJointInterface</hardwareInterface-->
      <!--hardwareInterface>EffortJointInterface</hardwareInterface-->
      <hardwareInterface>VelocityJointInterface</hardwareInterface>
      <mechanicalReduction>1</mechanicalReduction>
    </actuator>
  </transmission>
  <gazebo reference="r_indexend_joint">
    <implicitSpringDamper>0</implicitSpringDamper>
  </gazebo>
  <joint name="r_thumb_joint" type="revolute">
    <parent link="r_hand_link"/>
    <child link="r_thumb_link"/>
    <origin rpy="0 -0 0 " xyz="0 0.022355 -0.079645"/>
    <axis xyz="1 0 0"/>
    <limit effort="100" lower="-3.14159" upper="3.14159" velocity="0.5"/>
    <dynamics damping="0.2" friction="0"/>
  </joint>
  <transmission name="r_thumb_joint_trans">
    <type>transmission_interface/SimpleTransmission</type>
    <joint name="r_thumb_joint">
      <!-- dupricated in kinetic -->
      <!--hardwareInterface>hardware_interface/EffortJointInterface</hardwareInterface-->
      <!--hardwareInterface>EffortJointInterface</hardwareInterface-->
      <hardwareInterface>VelocityJointInterface</hardwareInterface>
    </joint>
    <actuator name="r_thumb_joint_motor">
      <!-- dupricated in kinetic -->
      <!--hardwareInterface>hardware_interface/EffortJointInterface</hardwareInterface-->
      <!--hardwareInterface>EffortJointInterface</hardwareInterface-->
      <hardwareInterface>VelocityJointInterface</hardwareInterface>
      <mechanicalReduction>1</mechanicalReduction>
    </actuator>
  </transmission>
  <gazebo reference="r_thumb_joint">
    <implicitSpringDamper>0</implicitSpringDamper>
  </gazebo>
  <!-- for ik eef link-->
  <link name="r_eef_grasp_link"/>
  <link name="r_eef_pick_link"/>
  <link name="r_thumb_tip_link"/>
  <link name="r_index_tip_link"/>
  <!-- for ik eef link-->
  <!-- for ik eef connector-->
  <joint name="r_eef_grasp_joint" type="fixed">
    <parent link="r_hand_link"/>
    <child link="r_eef_grasp_link"/>
    <origin rpy="0 1.5708 0 " xyz="0.0 0.04 -0.14"/>
  </joint>
  <joint name="r_eef_pick_joint" type="fixed">
    <parent link="r_hand_link"/>
    <child link="r_eef_pick_link"/>
    <origin rpy="0 1.5708 0 " xyz="0.0 0.07 -0.16"/>
  </joint>
  <joint name="r_thumb_tip_joint" type="fixed">
    <parent link="r_thumb_link"/>
    <child link="r_thumb_tip_link"/>
    <origin rpy="0 0 0 " xyz="0.0 0.035 -0.085"/>
  </joint>
  <joint name="r_index_tip_joint" type="fixed">
    <parent link="r_indexend_link"/>
    <child link="r_index_tip_link"/>
    <origin rpy="0 0 0 " xyz="0.0 0.02 0.0"/>
  </joint>
  <!-- for ik eef connector-->
  <joint name="upper_lower_connector" type="fixed">
    <parent link="lifter_top_link"/>
    <child link="waist_link"/>
    <origin rpy="0 0 0 " xyz="0.0 0.0 0.0"/>
  </joint>
  <!-- ============================   typeE_wheels  ============================ -->
  <link name="base_link"/>
  <link name="wheel_base_link">
    <visual>
      <origin rpy="0 -0 0" xyz="0.0 0.0 0.0"/>
      <geometry>
        <mesh filename="package://seed_r7_description/meshes/typeE_wheel/wheels_base.dae" scale="1 1 1"/>
      </geometry>
    </visual>
    <collision>
      <!--origin xyz="0.0 0.0 0.0" rpy="0 -0 0"/>
        <geometry>
          <mesh filename="package://seed_r7_description/meshes/typeE_wheel/wheels_base.dae" scale="1 1 1" />
        </geometry-->
      <origin rpy="0 -0 0" xyz="0.018 0.0 0.0375"/>
      <geometry>
        <box size="0.72 0.52 0.149"/>
      </geometry>
    </collision>
    <inertial>
      <mass value="70"/>
      <origin rpy="0 -0 0.0" xyz="0 0 0.04"/>
      <inertia ixx="0.528" ixy="0" ixz="0" iyy="2.02" iyz="0" izz="2.35"/>
    </inertial>
  </link>
  <gazebo reference="wheel_base_link">
    <mu1>0.9</mu1>
    <mu2>0.9</mu2>
  </gazebo>
  <link name="wheels_top_link">
    <visual>
      <origin rpy="0 -0 0" xyz="0.0 0.0 0.0"/>
      <geometry>
        <mesh filename="package://seed_r7_description/meshes/typeE_wheel/wheels_top.dae" scale="1 1 1"/>
      </geometry>
    </visual>
    <!-- no collision geometry -->
    <inertial>
      <mass value="1"/>
      <origin rpy="0 -0 0" xyz="0 0 0"/>
      <inertia ixx="0.528" ixy="0" ixz="0" iyy="2.02" iyz="0" izz="2.35"/>
    </inertial>
  </link>
  <gazebo reference="wheels_top_link">
    <mu1>0.9</mu1>
    <mu2>0.9</mu2>
  </gazebo>
  <link name="wheels_front_left_mecanum">
    <visual>
      <origin rpy="-1.57079632679 0 0" xyz="0.0 0.0 0.0"/>
      <geometry>
        <mesh filename="package://seed_r7_description/meshes/typeE_wheel/wheels_mecanum.dae" scale="1 1 1"/>
      </geometry>
    </visual>
    <collision>
      <origin rpy="-1.57079632679 0 0" xyz="0.0 0.0 0.0"/>
      <geometry>
        <!--cylinder length="0.046" radius="0.076" /-->
        <box size="0.152 0.152 0.046"/>
      </geometry>
    </collision>
    <inertial>
      <mass value="1"/>
      <origin rpy="0 -0 0" xyz="0 0 0"/>
      <inertia ixx="0.528" ixy="0" ixz="0" iyy="2.02" iyz="0" izz="2.35"/>
    </inertial>
  </link>
  <gazebo reference="wheels_front_left_mecanum">
    <mu1>0.25</mu1>
    <mu2>0.25</mu2>
  </gazebo>
  <link name="wheels_front_right_mecanum">
    <visual>
      <origin rpy="-1.57079632679 0 0" xyz="0.0 0.0 0.0"/>
      <geometry>
        <mesh filename="package://seed_r7_description/meshes/typeE_wheel/wheels_mecanum.dae" scale="1 1 1"/>
      </geometry>
    </visual>
    <collision>
      <origin rpy="-1.57079632679 0 0" xyz="0.0 0.0 0.0"/>
      <geometry>
        <!--cylinder length="0.046" radius="0.076" /-->
        <box size="0.152 0.152 0.046"/>
      </geometry>
    </collision>
    <inertial>
      <mass value="1"/>
      <origin rpy="0 -0 0" xyz="0 0 0"/>
      <inertia ixx="0.528" ixy="0" ixz="0" iyy="2.02" iyz="0" izz="2.35"/>
    </inertial>
  </link>
  <gazebo reference="wheels_front_left_mecanum">
    <mu1>0.25</mu1>
    <mu2>0.25</mu2>
  </gazebo>
  <link name="wheels_rear_left_mecanum">
    <visual>
      <origin rpy="-1.57079632679 0 0" xyz="0.0 0.0 0.0"/>
      <geometry>
        <mesh filename="package://seed_r7_description/meshes/typeE_wheel/wheels_mecanum.dae" scale="1 1 1"/>
      </geometry>
    </visual>
    <collision>
      <origin rpy="-1.57079632679 0 0" xyz="0.0 0.0 0.0"/>
      <geometry>
        <!--cylinder length="0.046" radius="0.076" /-->
        <box size="0.152 0.152 0.046"/>
      </geometry>
    </collision>
    <inertial>
      <mass value="1"/>
      <origin rpy="0 -0 0" xyz="0 0 0"/>
      <inertia ixx="0.528" ixy="0" ixz="0" iyy="2.02" iyz="0" izz="2.35"/>
    </inertial>
  </link>
  <gazebo reference="wheels_rear_left_mecanum">
    <mu1>0.25</mu1>
    <mu2>0.25</mu2>
  </gazebo>
  <link name="wheels_rear_right_mecanum">
    <visual>
      <origin rpy="-1.57079632679 0 0" xyz="0.0 0.0 0.0"/>
      <geometry>
        <mesh filename="package://seed_r7_description/meshes/typeE_wheel/wheels_mecanum.dae" scale="1 1 1"/>
      </geometry>
    </visual>
    <collision>
      <origin rpy="-1.57079632679 0 0" xyz="0.0 0.0 0.0"/>
      <geometry>
        <!--cylinder length="0.046" radius="0.076" /-->
        <box size="0.152 0.152 0.046"/>
      </geometry>
    </collision>
    <inertial>
      <mass value="1"/>
      <origin rpy="0 -0 0" xyz="0 0 0"/>
      <inertia ixx="0.528" ixy="0" ixz="0" iyy="2.02" iyz="0" izz="2.35"/>
    </inertial>
  </link>
  <gazebo reference="wheels_rear_right_mecanum">
    <mu1>0.25</mu1>
    <mu2>0.25</mu2>
  </gazebo>
  <link name="wheels_base_laser_link">
    <visual>
      <origin rpy="0 0 0" xyz="0.0 0.0 0.0"/>
      <geometry>
        <mesh filename="package://seed_r7_description/meshes/typeE_wheel/wheels_urg.dae" scale="1 1 1"/>
      </geometry>
    </visual>
    <collision>
      <origin rpy="0 -0 0" xyz="0.0 0.0 -0.0124"/>
      <geometry>
        <box size="0.08 0.1 0.07"/>
      </geometry>
    </collision>
    <inertial>
      <mass value="0.2"/>
      <origin rpy="0 -0 0" xyz="0 0 0"/>
      <inertia ixx="0.0528" ixy="0" ixz="0" iyy="0.0202" iyz="0" izz="0.0235"/>
    </inertial>
  </link>
  <gazebo reference="wheels_base_laser_link">
    <mu1>0.9</mu1>
    <mu2>0.9</mu2>
  </gazebo>
  <joint name="base_link_to_wheel_base_link_connector" type="fixed">
    <parent link="base_link"/>
    <child link="wheel_base_link"/>
    <origin rpy="0 0 0" xyz="0.0 0.0 0.075"/>
  </joint>
  <joint name="wheels_body_to_top_connector" type="fixed">
    <parent link="wheel_base_link"/>
    <child link="wheels_top_link"/>
    <origin rpy="0 0 0 " xyz="0.0 0.0 0.115"/>
  </joint>
  <joint name="wheels_body_to_front_left_mecanum_connector" type="fixed">
    <parent link="wheel_base_link"/>
    <child link="wheels_front_left_mecanum"/>
    <origin rpy="0 0 0" xyz="0.2265 0.19485 0"/>
  </joint>
  <joint name="wheels_body_to_front_right_mecanum_connector" type="fixed">
    <parent link="wheel_base_link"/>
    <child link="wheels_front_right_mecanum"/>
    <origin rpy="0 0 0" xyz="0.2265 -0.19485 0"/>
  </joint>
  <joint name="wheels_body_to_rear_left_mecanum_connector" type="fixed">
    <parent link="wheel_base_link"/>
    <child link="wheels_rear_left_mecanum"/>
    <origin rpy="0 0 0" xyz="-0.2265 0.19485 0"/>
  </joint>
  <joint name="wheels_body_to_rear_right_mecanum_connector" type="fixed">
    <parent link="wheel_base_link"/>
    <child link="wheels_rear_right_mecanum"/>
    <origin rpy="0 0 0" xyz="-0.2265 -0.19485 0"/>
  </joint>
  <joint name="wheels_body_to_base_laser_connector" type="fixed">
    <parent link="wheel_base_link"/>
    <child link="wheels_base_laser_link"/>
    <origin rpy="0 0 0" xyz="0.29 0 0.1324"/>
  </joint>
  <joint name="wheel_lifter_connector" type="fixed">
    <parent link="wheels_top_link"/>
    <child link="lifter_base_link"/>
    <origin rpy="0 0 0 " xyz="0.0 0.0 0.005"/>
  </joint>
  <!-- ============================   (typeC_lifter)   ============================ -->
  <link name="lifter_base_link">
    <visual>
      <origin rpy="0 -0 0" xyz="0 0 0"/>
      <geometry>
        <mesh filename="package://seed_r7_description/meshes/typeC_lifter/lifter_base.dae" scale="1 1 1"/>
      </geometry>
    </visual>
    <collision>
      <origin rpy="0 -0 0" xyz="0 0 0"/>
      <geometry>
        <mesh filename="package://seed_r7_description/meshes/typeC_lifter/lifter_base.dae" scale="1 1 1"/>
      </geometry>
    </collision>
    <inertial>
      <mass value="7.64604"/>
      <origin rpy="0 -0 0" xyz="-0.012819 -0.002679 0.007207"/>
      <inertia ixx="0.0658136" ixy="-0.000159462" ixz="0.010103" iyy="0.0504268" iyz="0.000173435" izz="0.0889772"/>
    </inertial>
  </link>
  <gazebo reference="lifter_base_link">
    <mu1>0.9</mu1>
    <mu2>0.9</mu2>
  </gazebo>
  <link name="leg_shank_link">
    <visual>
      <origin rpy="3.1415 -0 0" xyz="0.0 0.0 0"/>
      <geometry>
        <mesh filename="package://seed_r7_description/meshes/typeC_lifter/lifter_bone.dae" scale="1 1 1"/>
      </geometry>
    </visual>
    <collision>
      <origin rpy="3.1415 -0 0" xyz="0.0 0.0 0"/>
      <geometry>
        <mesh filename="package://seed_r7_description/meshes/typeC_lifter/lifter_bone.dae" scale="1 1 1"/>
      </geometry>
    </collision>
    <inertial>
      <mass value="2.06679"/>
      <!--origin xyz="0.081713 0.000812 -0.146934" rpy="0 -0 0"/-->
      <origin rpy="0 -0 0" xyz="0.051713 0.0 0.146934"/>
      <!--inertia ixx="0.0408818" ixy="-9.39301e-06" ixz="-0.000750165" iyy="0.0403969" iyz="-0.000120419" izz="0.00260982"/-->
      <inertia ixx="0.06" ixy="0.0" ixz="0.0" iyy="0.1" iyz="0.0" izz="0.06"/>
    </inertial>
  </link>
  <gazebo reference="leg_shank_link">
    <mu1>0.9</mu1>
    <mu2>0.9</mu2>
  </gazebo>
  <link name="leg_knee_link">
    <visual>
      <origin rpy="3.1415 -0 0" xyz="0.0 0.0 0"/>
      <geometry>
        <mesh filename="package://seed_r7_description/meshes/typeC_lifter/lifter_knee.dae" scale="1 1 1"/>
      </geometry>
    </visual>
    <collision>
      <origin rpy="3.1415 -0 0" xyz="0.0 0.0 0"/>
      <geometry>
        <mesh filename="package://seed_r7_description/meshes/typeC_lifter/lifter_knee.dae" scale="1 1 1"/>
      </geometry>
    </collision>
    <inertial>
      <mass value="2.06679"/>
      <!--origin xyz="0.081713 0.000812 -0.146934" rpy="0 -0 0"/-->
      <origin rpy="0 -0 0" xyz="-0.031713 0.0 0.046934"/>
      <!--inertia ixx="0.0408818" ixy="-9.39301e-06" ixz="-0.000750165" iyy="0.0403969" iyz="-0.000120419" izz="0.00260982"/-->
      <inertia ixx="0.06" ixy="0.0" ixz="0.0" iyy="0.1" iyz="0.0" izz="0.06"/>
    </inertial>
  </link>
  <gazebo reference="leg_knee_link">
    <mu1>0.9</mu1>
    <mu2>0.9</mu2>
  </gazebo>
  <link name="leg_thigh_link">
    <visual>
      <origin rpy="0 0 0" xyz="0 0 0.25"/>
      <geometry>
        <mesh filename="package://seed_r7_description/meshes/typeC_lifter/lifter_bone.dae" scale="1 1 1"/>
      </geometry>
    </visual>
    <collision>
      <origin rpy="0 0 0" xyz="0 0 0.25"/>
      <geometry>
        <mesh filename="package://seed_r7_description/meshes/typeC_lifter/lifter_bone.dae" scale="1 1 1"/>
      </geometry>
    </collision>
    <inertial>
      <mass value="2.62321"/>
      <!--origin xyz="0.0587169 0 -0.135292" rpy="0 -0 0"/-->
      <origin rpy="0 -0 0" xyz="-0.0587169 0 0.135292"/>
      <inertia ixx="0.0161595" ixy="-9.27234e-05" ixz="0.00262839" iyy="0.0166415" iyz="-0.00017447" izz="0.00477281"/>
    </inertial>
  </link>
  <gazebo reference="leg_thigh_link">
    <mu1>0.9</mu1>
    <mu2>0.9</mu2>
  </gazebo>
  <link name="leg_base_link">
    <visual>
      <origin rpy="3.1415920 0 0" xyz="0 0 0.05"/>
      <geometry>
        <mesh filename="package://seed_r7_description/meshes/typeC_lifter/lifter_base.dae" scale="1 1 1"/>
      </geometry>
    </visual>
    <collision>
      <origin rpy="3.1415920 0 0" xyz="0 0 0.05"/>
      <geometry>
        <mesh filename="package://seed_r7_description/meshes/typeC_lifter/lifter_base.dae" scale="1 1 1"/>
      </geometry>
    </collision>
    <inertial>
      <mass value="7.64604"/>
      <origin rpy="0 -0 0" xyz="-0.012819 -0.002679 0.007207"/>
      <inertia ixx="0.0658136" ixy="-0.000159462" ixz="0.010103" iyy="0.0504268" iyz="0.000173435" izz="0.0889772"/>
    </inertial>
  </link>
  <gazebo reference="leg_base_link">
    <mu1>0.9</mu1>
    <mu2>0.9</mu2>
  </gazebo>
  <link name="lifter_top_link">
    <visual>
      <origin rpy="0 -0 0" xyz="0 0 0"/>
      <geometry>
        <mesh filename="package://seed_r7_description/meshes/typeC_lifter/lifter_top.dae" scale="1 1 1"/>
      </geometry>
    </visual>
    <collision>
      <origin rpy="0 -0 0" xyz="0 0 0"/>
      <geometry>
        <mesh filename="package://seed_r7_description/meshes/typeC_lifter/lifter_top.dae" scale="1 1 1"/>
      </geometry>
    </collision>
    <inertial>
      <mass value="1.0"/>
      <origin rpy="0 0 0" xyz="0.0 0.0 0.0"/>
      <inertia ixx="0.03" ixy="0.0" ixz="0.0" iyy="0.03" iyz="0.0" izz="0.04"/>
    </inertial>
  </link>
  <gazebo reference="lifter_top_link">
    <mu1>0.9</mu1>
    <mu2>0.9</mu2>
  </gazebo>
  <joint name="lifter_top_connector" type="fixed">
    <parent link="leg_base_link"/>
    <child link="lifter_top_link"/>
    <origin rpy="0 0 0" xyz="0 0 0.055"/>
  </joint>
  <joint name="knee_joint_mimic" type="revolute">
    <parent link="leg_thigh_link"/>
    <child link="leg_base_link"/>
    <origin rpy="0 0 0" xyz="0 0 0.25"/>
    <axis xyz="0 -1 0"/>
    <mimic joint="knee_joint" multiplier="-1" offset="0"/>
    <limit effort="10000" lower="0" upper="1.5707" velocity="0.5"/>
    <!-- just invert of knee_joint -->
  </joint>
  <joint name="knee_joint" type="revolute">
    <!-- rename "knee_joint_thigh_dummy" -->
    <parent link="leg_knee_link"/>
    <child link="leg_thigh_link"/>
    <origin rpy="0 0 0" xyz="0 0 0.12"/>
    <axis xyz="0 -1 0"/>
    <limit effort="10000" lower="-1.5707" upper="0" velocity="0.5"/>
  </joint>
  <transmission name="knee_joint_trans">
    <type>transmission_interface/SimpleTransmission</type>
    <joint name="knee_joint">
      <!-- dupricated in kinetic -->
      <!--hardwareInterface>hardware_interface/EffortJointInterface</hardwareInterface-->
      <!--hardwareInterface>EffortJointInterface</hardwareInterface-->
      <hardwareInterface>VelocityJointInterface</hardwareInterface>
    </joint>
    <actuator name="knee_joint_motor">
      <!-- dupricated in kinetic -->
      <!--hardwareInterface>hardware_interface/EffortJointInterface</hardwareInterface-->
      <!--hardwareInterface>EffortJointInterface</hardwareInterface-->
      <hardwareInterface>VelocityJointInterface</hardwareInterface>
      <mechanicalReduction>1</mechanicalReduction>
    </actuator>
  </transmission>
  <gazebo reference="knee_joint">
    <implicitSpringDamper>0</implicitSpringDamper>
  </gazebo>
  <joint name="ankle_joint" type="revolute">
    <parent link="lifter_base_link"/>
    <child link="leg_shank_link"/>
    <origin rpy="0 0 0" xyz="0 0 0.05"/>
    <axis xyz="0 -1 0"/>
    <limit effort="10000" lower="0" upper="1.5707" velocity="0.5"/>
    <dynamics damping="0.2" friction="0"/>
  </joint>
  <transmission name="ankle_joint_trans">
    <type>transmission_interface/SimpleTransmission</type>
    <joint name="ankle_joint">
      <!-- dupricated in kinetic -->
      <!--hardwareInterface>hardware_interface/EffortJointInterface</hardwareInterface-->
      <!--hardwareInterface>EffortJointInterface</hardwareInterface-->
      <hardwareInterface>VelocityJointInterface</hardwareInterface>
    </joint>
    <actuator name="ankle_joint_motor">
      <!-- dupricated in kinetic -->
      <!--hardwareInterface>hardware_interface/EffortJointInterface</hardwareInterface-->
      <!--hardwareInterface>EffortJointInterface</hardwareInterface-->
      <hardwareInterface>VelocityJointInterface</hardwareInterface>
      <mechanicalReduction>1</mechanicalReduction>
    </actuator>
  </transmission>
  <gazebo reference="ankle_joint">
    <implicitSpringDamper>0</implicitSpringDamper>
  </gazebo>
  <!--- mimic joints -->
  <!-- requried -->
  <joint name="ankle_joint_mimic" type="revolute">
    <parent link="leg_shank_link"/>
    <child link="leg_knee_link"/>
    <origin rpy="0 0 0" xyz="0 0 0.25"/>
    <axis xyz="0 -1 0"/>
    <mimic joint="ankle_joint" multiplier="-1" offset="0"/>
    <limit effort="10000" lower="-1.5707" upper="0" velocity="0.5"/>
    <!-- just invert of ankle_joint -->
  </joint>
  <!-- redundant -->
  <link name="leg_shank_link_dummy">
    <visual>
      <geometry>
        <mesh filename="package://seed_r7_description/meshes/typeC_lifter/lifter_bone_dummy.dae" scale="1 1 1"/>
      </geometry>
      <origin rpy="0 0 0" xyz="0 0 0.25"/>
    </visual>
    <inertial>
      <!-- for gazebo visualization -->
      <mass value="0.4"/>
      <origin rpy="0 0 0" xyz="-0.04 0.0 0.14"/>
      <inertia ixx="0.001" ixy="0" ixz="0" iyy="0.001" iyz="0" izz="0.001"/>
    </inertial>
  </link>
  <link name="leg_thigh_link_dummy">
    <visual>
      <geometry>
        <mesh filename="package://seed_r7_description/meshes/typeC_lifter/lifter_bone_dummy.dae" scale="1 1 1"/>
      </geometry>
      <origin rpy="0 0 0" xyz="0 0 0.25"/>
    </visual>
    <inertial>
      <!-- for gazebo visualization -->
      <mass value="0.4"/>
      <origin rpy="0 0 0" xyz="-0.04 0.0 0.14"/>
      <inertia ixx="0.001" ixy="0" ixz="0" iyy="0.001" iyz="0" izz="0.001"/>
    </inertial>
  </link>
  <joint name="ankle_joint_dummy" type="continuous">
    <parent link="lifter_base_link"/>
    <child link="leg_shank_link_dummy"/>
    <origin rpy="0 0 0" xyz="0.03182 0 0.08182"/>
    <axis xyz="0 -1 0"/>
    <mimic joint="ankle_joint" multiplier="1" offset="0"/>
  </joint>
  <joint name="knee_joint_dummy" type="continuous">
    <parent link="leg_knee_link"/>
    <child link="leg_thigh_link_dummy"/>
    <origin rpy="0 0 0" xyz="0.03182 0 0.08818"/>
    <axis xyz="0 1 0"/>
    <mimic joint="knee_joint" multiplier="-1" offset="0"/>
  </joint>
</robot>

